P_03
P_04
P_05
P_06
P_09
P_10
P_12
P_13
P_14
P_18
P_19
P_20
P_01
P_02
P_16
P_17
  0%|                                                                                                                                                                                     | 0/32 [00:00<?, ?it/s]
Traceback (most recent call last):
  File "main.py", line 65, in <module>
    main()
  File "main.py", line 58, in main
    train_model(config)
  File "/workspace/tfg_hhernandez/utils/train.py", line 49, in train_model
    for batch, (features, label) in enumerate(tqdm(train_loader)):
  File "/usr/local/lib/python3.8/dist-packages/tqdm/std.py", line 1181, in __iter__
    for obj in iterable:
  File "/usr/local/lib/python3.8/dist-packages/torch/utils/data/dataloader.py", line 631, in __next__
    data = self._next_data()
  File "/usr/local/lib/python3.8/dist-packages/torch/utils/data/dataloader.py", line 1346, in _next_data
    return self._process_data(data)
  File "/usr/local/lib/python3.8/dist-packages/torch/utils/data/dataloader.py", line 1372, in _process_data
    data.reraise()
  File "/usr/local/lib/python3.8/dist-packages/torch/_utils.py", line 705, in reraise
    raise exception
ValueError: Caught ValueError in DataLoader worker process 0.
Original Traceback (most recent call last):
  File "/usr/local/lib/python3.8/dist-packages/torch/utils/data/_utils/worker.py", line 308, in _worker_loop
    data = fetcher.fetch(index)  # type: ignore[possibly-undefined]
  File "/usr/local/lib/python3.8/dist-packages/torch/utils/data/_utils/fetch.py", line 51, in fetch
    data = [self.dataset[idx] for idx in possibly_batched_index]
  File "/usr/local/lib/python3.8/dist-packages/torch/utils/data/_utils/fetch.py", line 51, in <listcomp>
    data = [self.dataset[idx] for idx in possibly_batched_index]
  File "/workspace/tfg_hhernandez/dataset/ADL.py", line 160, in __getitem__
    video_name,start_frame,end_frame,action=self.sequences[index]
ValueError: too many values to unpack (expected 4)
